{
 "cells": [
  {
   "cell_type": "markdown",
   "id": "21fc2e28",
   "metadata": {},
   "source": [
    "# `Pydantic` Library"
   ]
  },
  {
   "cell_type": "markdown",
   "id": "672c1bc1",
   "metadata": {},
   "source": [
    "`Pydantic` allows users to specify the type of each attribute and performs type validation when instances are created. In a regular Python class, attribute types are typically dynamic and hard to track."
   ]
  },
  {
   "cell_type": "code",
   "execution_count": null,
   "id": "08abc9fc",
   "metadata": {},
   "outputs": [
    {
     "name": "stdout",
     "output_type": "stream",
     "text": [
      "name='wang' age=18 address=None\n"
     ]
    }
   ],
   "source": [
    "from pydantic import BaseModel\n",
    "from typing import Optional\n",
    "\n",
    "class Person(BaseModel):\n",
    "    name: str\n",
    "    age: int\n",
    "    address: Optional[str] = None\n",
    "\n",
    "p1 = Person(name=\"wang\", age=18)\n",
    "p2 = Person(name=\"chen\", age=20)\n",
    "\n",
    "print()"
   ]
  },
  {
   "cell_type": "code",
   "execution_count": 2,
   "id": "e5531b2f",
   "metadata": {},
   "outputs": [
    {
     "ename": "ValidationError",
     "evalue": "1 validation error for Person\nname\n  Input should be a valid string [type=string_type, input_value=123, input_type=int]\n    For further information visit https://errors.pydantic.dev/2.9/v/string_type",
     "output_type": "error",
     "traceback": [
      "\u001b[0;31m---------------------------------------------------------------------------\u001b[0m",
      "\u001b[0;31mValidationError\u001b[0m                           Traceback (most recent call last)",
      "Cell \u001b[0;32mIn[2], line 1\u001b[0m\n\u001b[0;32m----> 1\u001b[0m p3 \u001b[38;5;241m=\u001b[39m \u001b[43mPerson\u001b[49m\u001b[43m(\u001b[49m\u001b[43mname\u001b[49m\u001b[38;5;241;43m=\u001b[39;49m\u001b[38;5;241;43m123\u001b[39;49m\u001b[43m,\u001b[49m\u001b[43m \u001b[49m\u001b[43mage\u001b[49m\u001b[38;5;241;43m=\u001b[39;49m\u001b[38;5;241;43m23\u001b[39;49m\u001b[43m)\u001b[49m\n",
      "File \u001b[0;32m/opt/anaconda3/envs/ai-agent-py310/lib/python3.10/site-packages/pydantic/main.py:212\u001b[0m, in \u001b[0;36mBaseModel.__init__\u001b[0;34m(self, **data)\u001b[0m\n\u001b[1;32m    210\u001b[0m \u001b[38;5;66;03m# `__tracebackhide__` tells pytest and some other tools to omit this function from tracebacks\u001b[39;00m\n\u001b[1;32m    211\u001b[0m __tracebackhide__ \u001b[38;5;241m=\u001b[39m \u001b[38;5;28;01mTrue\u001b[39;00m\n\u001b[0;32m--> 212\u001b[0m validated_self \u001b[38;5;241m=\u001b[39m \u001b[38;5;28;43mself\u001b[39;49m\u001b[38;5;241;43m.\u001b[39;49m\u001b[43m__pydantic_validator__\u001b[49m\u001b[38;5;241;43m.\u001b[39;49m\u001b[43mvalidate_python\u001b[49m\u001b[43m(\u001b[49m\u001b[43mdata\u001b[49m\u001b[43m,\u001b[49m\u001b[43m \u001b[49m\u001b[43mself_instance\u001b[49m\u001b[38;5;241;43m=\u001b[39;49m\u001b[38;5;28;43mself\u001b[39;49m\u001b[43m)\u001b[49m\n\u001b[1;32m    213\u001b[0m \u001b[38;5;28;01mif\u001b[39;00m \u001b[38;5;28mself\u001b[39m \u001b[38;5;129;01mis\u001b[39;00m \u001b[38;5;129;01mnot\u001b[39;00m validated_self:\n\u001b[1;32m    214\u001b[0m     warnings\u001b[38;5;241m.\u001b[39mwarn(\n\u001b[1;32m    215\u001b[0m         \u001b[38;5;124m'\u001b[39m\u001b[38;5;124mA custom validator is returning a value other than `self`.\u001b[39m\u001b[38;5;130;01m\\n\u001b[39;00m\u001b[38;5;124m'\u001b[39m\n\u001b[1;32m    216\u001b[0m         \u001b[38;5;124m\"\u001b[39m\u001b[38;5;124mReturning anything other than `self` from a top level model validator isn\u001b[39m\u001b[38;5;124m'\u001b[39m\u001b[38;5;124mt supported when validating via `__init__`.\u001b[39m\u001b[38;5;130;01m\\n\u001b[39;00m\u001b[38;5;124m\"\u001b[39m\n\u001b[1;32m    217\u001b[0m         \u001b[38;5;124m'\u001b[39m\u001b[38;5;124mSee the `model_validator` docs (https://docs.pydantic.dev/latest/concepts/validators/#model-validators) for more details.\u001b[39m\u001b[38;5;124m'\u001b[39m,\n\u001b[1;32m    218\u001b[0m         category\u001b[38;5;241m=\u001b[39m\u001b[38;5;28;01mNone\u001b[39;00m,\n\u001b[1;32m    219\u001b[0m     )\n",
      "\u001b[0;31mValidationError\u001b[0m: 1 validation error for Person\nname\n  Input should be a valid string [type=string_type, input_value=123, input_type=int]\n    For further information visit https://errors.pydantic.dev/2.9/v/string_type"
     ]
    }
   ],
   "source": [
    "p3 = Person(name=123, age=23)"
   ]
  },
  {
   "cell_type": "code",
   "execution_count": null,
   "id": "8889f81c",
   "metadata": {},
   "outputs": [],
   "source": [
    "user"
   ]
  }
 ],
 "metadata": {
  "kernelspec": {
   "display_name": "ai-agent-py310",
   "language": "python",
   "name": "python3"
  },
  "language_info": {
   "codemirror_mode": {
    "name": "ipython",
    "version": 3
   },
   "file_extension": ".py",
   "mimetype": "text/x-python",
   "name": "python",
   "nbconvert_exporter": "python",
   "pygments_lexer": "ipython3",
   "version": "3.10.18"
  }
 },
 "nbformat": 4,
 "nbformat_minor": 5
}
